<?xml version="1.0" ?>
<robot name="s1100851" xmlns:xacro="http://www.ros.org/wiki/xacro">

<xacro:include filename="$(find s1100851_description)/urdf/materials.xacro" />
<xacro:include filename="$(find s1100851_description)/urdf/s1100851.trans" />
<xacro:include filename="$(find s1100851_description)/urdf/s1100851.gazebo" />
<link name="base_link">
  <inertial>
    <origin xyz="0.054600218095921464 0.050490875959185964 0.021502333541230812" rpy="0 0 0"/>
    <mass value="0.5126119186938088"/>
    <inertia ixx="0.000363" iyy="0.000398" izz="0.000735" ixy="9e-06" iyz="-8e-06" ixz="2e-05"/>
  </inertial>
  <visual>
    <origin xyz="0 0 0" rpy="0 0 0"/>
    <geometry>
      <mesh filename="package://s1100851_description/meshes/base_link.stl" scale="0.001 0.001 0.001"/>
    </geometry>
    <material name="silver"/>
  </visual>
  <collision>
    <origin xyz="0 0 0" rpy="0 0 0"/>
    <geometry>
      <mesh filename="package://s1100851_description/meshes/base_link.stl" scale="0.001 0.001 0.001"/>
    </geometry>
  </collision>
</link>

<link name="right_wheel_1">
  <inertial>
    <origin xyz="-1.3877787807814457e-17 -0.005 -6.938893903907228e-18" rpy="0 0 0"/>
    <mass value="0.1541343895667492"/>
    <inertia ixx="2.5e-05" iyy="4.8e-05" izz="2.5e-05" ixy="0.0" iyz="-0.0" ixz="-0.0"/>
  </inertial>
  <visual>
    <origin xyz="-0.05 -0.0 -0.02" rpy="0 0 0"/>
    <geometry>
      <mesh filename="package://s1100851_description/meshes/right_wheel_1.stl" scale="0.001 0.001 0.001"/>
    </geometry>
    <material name="silver"/>
  </visual>
  <collision>
    <origin xyz="-0.05 -0.0 -0.02" rpy="0 0 0"/>
    <geometry>
      <mesh filename="package://s1100851_description/meshes/right_wheel_1.stl" scale="0.001 0.001 0.001"/>
    </geometry>
  </collision>
</link>

<link name="left_wheel_1">
  <inertial>
    <origin xyz="-1.3877787807814457e-17 0.0049999999999999906 -3.469446951953614e-18" rpy="0 0 0"/>
    <mass value="0.15413438956674924"/>
    <inertia ixx="2.5e-05" iyy="4.8e-05" izz="2.5e-05" ixy="-0.0" iyz="-0.0" ixz="-0.0"/>
  </inertial>
  <visual>
    <origin xyz="-0.05 -0.1 -0.02" rpy="0 0 0"/>
    <geometry>
      <mesh filename="package://s1100851_description/meshes/left_wheel_1.stl" scale="0.001 0.001 0.001"/>
    </geometry>
    <material name="silver"/>
  </visual>
  <collision>
    <origin xyz="-0.05 -0.1 -0.02" rpy="0 0 0"/>
    <geometry>
      <mesh filename="package://s1100851_description/meshes/left_wheel_1.stl" scale="0.001 0.001 0.001"/>
    </geometry>
  </collision>
</link>

<link name="lider_1">
  <inertial>
    <origin xyz="2.0816681711721685e-17 0.0 0.0030000000000000027" rpy="0 0 0"/>
    <mass value="0.0036992253496019776"/>
    <inertia ixx="0.0" iyy="0.0" izz="0.0" ixy="0.0" iyz="0.0" ixz="0.0"/>
  </inertial>
  <visual>
    <origin xyz="-0.055 -0.05 -0.035" rpy="0 0 0"/>
    <geometry>
      <mesh filename="package://s1100851_description/meshes/lider_1.stl" scale="0.001 0.001 0.001"/>
    </geometry>
    <material name="silver"/>
  </visual>
  <collision>
    <origin xyz="-0.055 -0.05 -0.035" rpy="0 0 0"/>
    <geometry>
      <mesh filename="package://s1100851_description/meshes/lider_1.stl" scale="0.001 0.001 0.001"/>
    </geometry>
  </collision>
</link>

<link name="camera_1">
  <inertial>
    <origin xyz="2.7755575615628914e-17 -2.1522353452207987e-07 0.004500000000000004" rpy="0 0 0"/>
    <mass value="0.006392789395338336"/>
    <inertia ixx="0.0" iyy="0.0" izz="0.0" ixy="0.0" iyz="0.0" ixz="0.0"/>
  </inertial>
  <visual>
    <origin xyz="-0.055 -0.067867 -0.035" rpy="0 0 0"/>
    <geometry>
      <mesh filename="package://s1100851_description/meshes/camera_1.stl" scale="0.001 0.001 0.001"/>
    </geometry>
    <material name="silver"/>
  </visual>
  <collision>
    <origin xyz="-0.055 -0.067867 -0.035" rpy="0 0 0"/>
    <geometry>
      <mesh filename="package://s1100851_description/meshes/camera_1.stl" scale="0.001 0.001 0.001"/>
    </geometry>
  </collision>
</link>

<joint name="Revolute 1" type="continuous">
  <origin xyz="0.05 0.0 0.02" rpy="0 0 0"/>
  <parent link="base_link"/>
  <child link="right_wheel_1"/>
  <axis xyz="0.0 -1.0 0.0"/>
</joint>

<joint name="Revolute 2" type="continuous">
  <origin xyz="0.05 0.1 0.02" rpy="0 0 0"/>
  <parent link="base_link"/>
  <child link="left_wheel_1"/>
  <axis xyz="0.0 1.0 0.0"/>
</joint>

<joint name="Rigid 3" type="fixed">
  <origin xyz="0.055 0.05 0.035" rpy="0 0 0"/>
  <parent link="base_link"/>
  <child link="lider_1"/>
</joint>

<joint name="Rigid 4" type="fixed">
  <origin xyz="0.055 0.067867 0.035" rpy="0 0 0"/>
  <parent link="base_link"/>
  <child link="camera_1"/>
</joint>

</robot>
